Workbook

Sheet Read Me First
B2: Manual Test Suite — My Demo App (Android)
B4: Application | C4: My Demo App (Android), package com.saucelabs.mydemoapp.android
B5: Source | C5: https://github.com/saucelabs/my-demo-app-android/releases (open-source demo app built for QA practice)
B6: Author | C6: Akanksh Gurupadappa Akki
B7: Total test cases | C7: 164
B8: Priority split | C8: P1 66 · P2 69 · P3 29
B9: Modules | C9: 15
B11: HOW TO USE THIS WORKBOOK
B12: Columns A to L | C12: The designed test cases. Read only — do not edit these during execution.
B13: Columns M to R | C13: Yours to fill in as you execute (shaded yellow): Status, Actual Result, Executed On, Defect ID, Device, Notes.
B14: Status values | C14: Pass · Fail · Blocked · Not Run · N/A (dropdown provided)
B15: Blocked vs Fail | C15: Use Blocked when an earlier defect made the case impossible to run. Use Fail only when you ran it and it did not behave as expected. This distinction keeps the coverage report honest.
B16: Dashboard | C16: The Dashboard tab calculates everything automatically from column M. Never type into its shaded result cells.
B17: Filtering | C17: Every column has an autofilter. Filter Type to work through one testing document at a time, or Priority = P1 for the release gate.
B19: EXAMPLE ROW
B20: Example | C20: TC-CART-003 | Status: Fail | Actual Result: 'Displayed total 64.98; hand calculation 2 x 29.49 + 5.99 = 64.97. Off by one cent.' | Executed On: 2026-08-20 | Defect ID: BUG-004 | Device: Pixel 7 / Android 14 | Notes: 'Reproduced 5/5'
B22: EVIDENCE | C22: Capture a screenshot or recording BEFORE moving on from any failure. Commands are in evidence/README.md.
B24: DATA PROTECTION
B25: Rule | C25: Use only fictional names and obvious dummy card numbers such as 4111111111111111. Never enter real personal or payment data, and never record any in this workbook or in evidence files.

Sheet Test Cases
A1: ID | B1: Module | C1: Title | D1: Type | E1: Priority | F1: Journey Stage | G1: Preconditions | H1: Steps | I1: Expected Result | J1: Technique | K1: Risk ID | L1: Automation Candidate | M1: Status | N1: Actual Result | O1: Executed On | P1: Defect ID | Q1: Device | R1: Notes
A2: TC-LOGIN-001 | B2: Login & Authentication | C2: Login screen is reachable from the menu and renders all its controls | D2: Smoke | E2: P1 | F2: Account | G2: App installed and launched. User is logged out. | H2: 1. Tap the hamburger menu icon (top left) 2. Tap 'Log In' 3. Observe the screen | I2: The Login screen opens with: a 'Login' heading, the helper text about selecting a username, a Usernames list, a Username field, a Password field and a Login button. Nothing is cut off or overlapping. | J2: Specification-based (use case) | K2: R-01 | L2: Yes | M2: Not Run
A3: TC-LOGIN-002 | B3: Login & Authentication | C3: Tapping a listed username auto-populates both the username and password fields | D3: Functional | E3: P1 | F3: Account | G3: User is on the Login screen. | H3: 1. Read the helper text on screen — it states that tapping a username auto-populates the credentials 2. Tap the first listed username 3. Observe the Username field 4. Observe the Password field | I3: Both fields are populated. The Username field contains exactly the username that was tapped. The Password field contains a masked value. No field is left empty. | J3: Specification-based (use case) | K3: R-01 | L3: Yes | M3: Not Run
A4: TC-LOGIN-003 | B4: Login & Authentication | C4: Valid credentials log the user in successfully | D4: Smoke | E4: P1 | F4: Account | G4: User is on the Login screen and logged out. | H4: 1. Tap the standard (non-locked-out) username in the list to auto-populate credentials 2. Tap Login 3. Observe the resulting screen 4. Open the menu and check the Log In / Log Out entry | I4: Login succeeds. The user is taken to the Catalog (or back to the screen that required login). The menu now shows 'Log Out' instead of 'Log In'. No error message is displayed. | J4: Specification-based (use case) | K4: R-01 | L4: Yes | M4: Not Run
A5: TC-LOGIN-004 | B5: Login & Authentication | C5: The locked-out user is refused with a clear, specific message | D5: Functional | E5: P1 | F5: Account | G5: User is on the Login screen. The list marks one username as locked out. | H5: 1. Tap the username labelled as locked out to auto-populate credentials 2. Tap Login 3. Read the error message exactly as displayed 4. Confirm whether the user is still on the Login screen | I5: Login is refused. An error states the user has been locked out — it does not say 'wrong password', because that would be misleading. The user remains on the Login screen with the entered username retained. | J5: Specification-based (error guessing) | K5: R-01 | L5: Yes | M5: Not Run
A6: TC-LOGIN-005 | B6: Login & Authentication | C6: Submitting with an empty username shows a username-specific validation error | D6: Negative | E6: P1 | F6: Account | G6: User is on the Login screen. Both fields empty. | H6: 1. Leave the Username field empty 2. Type any value into the Password field 3. Tap Login 4. Observe which field is flagged and read the message | I6: A validation error appears on the Username field stating that a username is required. The Password field is not flagged. No login attempt is made and the screen does not change. | J6: Equivalence partitioning (invalid class: absent) | K6: R-02 | L6: Yes | M6: Not Run
A7: TC-LOGIN-006 | B7: Login & Authentication | C7: Submitting with an empty password shows a password-specific validation error | D7: Negative | E7: P1 | F7: Account | G7: User is on the Login screen. | H7: 1. Populate the Username field with a valid username 2. Leave the Password field empty 3. Tap Login 4. Observe which field is flagged and read the message | I7: A validation error appears on the Password field stating that a password is required. The Username field is not flagged. No login attempt is made. | J7: Equivalence partitioning (invalid class: absent) | K7: R-02 | L7: Yes | M7: Not Run
A8: TC-LOGIN-007 | B8: Login & Authentication | C8: Submitting with both fields empty flags both fields, not just the first | D8: Negative | E8: P2 | F8: Account | G8: User is on the Login screen with both fields empty. | H8: 1. Tap Login without typing anything 2. Observe both fields | I8: Both fields show their own validation error simultaneously. The form does not stop at the first error, which would force the user through two round trips to discover both problems. | J8: Equivalence partitioning | K8: R-02 | L8: Yes | M8: Not Run
A9: TC-LOGIN-008 | B9: Login & Authentication | C9: An unrecognised username is rejected without revealing whether the account exists | D9: Negative | E9: P2 | F9: Account | G9: User is on the Login screen. | H9: 1. Type 'nosuchuser@example.com' into Username 2. Type any password 3. Tap Login 4. Read the error message | I9: Login is refused with a generic credential error. The message does not state 'this user does not exist', because that discloses which email addresses are registered — an account-enumeration weakness. | J9: Error guessing / security-adjacent | K9: R-03 | L9: No | M9: Not Run
A10: TC-LOGIN-009 | B10: Login & Authentication | C10: A valid username with a wrong password is rejected | D10: Negative | E10: P1 | F10: Account | G10: User is on the Login screen. | H10: 1. Tap a listed username to populate the fields 2. Clear the Password field and type 'wrongpassword' 3. Tap Login 4. Read the error and confirm the screen did not change | I10: Login is refused with a credential error. The user remains on the Login screen. No partial access is granted — for example, the menu must still show 'Log In'. | J10: Equivalence partitioning (invalid class: wrong value) | K10: R-01 | L10: Yes | M10: Not Run
A11: TC-LOGIN-010 | B11: Login & Authentication | C11: Password input is masked and not readable on screen | D11: Functional | E11: P1 | F11: Account | G11: User is on the Login screen. | H11: 1. Tap the Password field 2. Type a password slowly, watching the field 3. Take a screenshot of the screen 4. If a show/hide toggle exists, use it and observe | I11: Characters are replaced with dots or asterisks. At most the last typed character is briefly visible, which is standard Android behaviour. The screenshot contains no readable password. If a reveal toggle exists it defaults to hidden. | J11: Security-adjacent / specification-based | K11: R-03 | L11: No | M11: Not Run
A12: TC-LOGIN-011 | B12: Login & Authentication | C12: Password is not recoverable from the app switcher preview | D12: Negative | E12: P2 | F12: Account | G12: User is on the Login screen with a password typed in. | H12: 1. Type a password into the field 2. Open the Android app switcher (recents) 3. Look at the app's thumbnail preview 4. Return to the app | I12: The recents thumbnail either hides the screen contents or shows the password masked. A plaintext password visible in the app switcher would be a real privacy defect. | J12: Error guessing / security-adjacent | K12: R-03 | L12: No | M12: Not Run
A13: TC-LOGIN-012 | B13: Login & Authentication | C13: Username field accepts a maximum-length input without breaking the layout | D13: Boundary | E13: P3 | F13: Account | G13: User is on the Login screen. A 256-character string is on the clipboard. | H13: 1. Paste a 256-character string into the Username field 2. Observe whether the field truncates, scrolls or overflows 3. Tap Login 4. Observe the result | I13: The field either enforces a maximum length or scrolls its content. Text does not overflow outside the field's bounds and does not push other controls off screen. Login is refused cleanly with no crash. | J13: Boundary value analysis (upper bound) | K13: R-02 | L13: No | M13: Not Run
... A165: TC-XCUT-020 | B165: Cross-cutting | C165: Uninstalling and reinstalling the app produces a genuinely clean state | D165: Functional | E165: P3 | F165: Cross-cutting | G165: App installed with a populated cart and an active session. | H165: 1. Note the cart contents and login state 2. Uninstall: adb uninstall com.saucelabs.mydemoapp.android 3. Reinstall the APK: adb install <path-to-apk> 4. Launch the app and inspect the cart and login state | I165: The app starts completely fresh: empty cart, logged out, default sort. Data surviving an uninstall would indicate storage outside the app sandbox, which is both a defect and a privacy concern. | J165: State transition testing (clean install) | K165: R-05 | L165: No | M165: Not Run

Sheet Dashboard
B2: Execution Dashboard
B3: Every figure is calculated from the Status column on the Test Cases tab. Do not type into the shaded cells.
B5: BY PRIORITY
B6: Priority | C6: Planned | D6: Pass | E6: Fail | F6: Blocked | G6: Not Run | H6: Pass rate
B7: P1 | C7: =COUNTIF('Test Cases'!$E$2:$E$165,$B7) | D7: =COUNTIFS('Test Cases'!$E$2:$E$165,$B7,'Test Cases'!$M$2:$M$165,"Pass") | E7: =COUNTIFS('Test Cases'!$E$2:$E$165,$B7,'Test Cases'!$M$2:$M$165,"Fail") | F7: =COUNTIFS('Test Cases'!$E$2:$E$165,$B7,'Test Cases'!$M$2:$M$165,"Blocked") | G7: =COUNTIFS('Test Cases'!$E$2:$E$165,$B7,'Test Cases'!$M$2:$M$165,"Not Run") | H7: =IFERROR(D7/(D7+E7),0)
B8: P2 | C8: =COUNTIF('Test Cases'!$E$2:$E$165,$B8) | D8: =COUNTIFS('Test Cases'!$E$2:$E$165,$B8,'Test Cases'!$M$2:$M$165,"Pass") | E8: =COUNTIFS('Test Cases'!$E$2:$E$165,$B8,'Test Cases'!$M$2:$M$165,"Fail") | F8: =COUNTIFS('Test Cases'!$E$2:$E$165,$B8,'Test Cases'!$M$2:$M$165,"Blocked") | G8: =COUNTIFS('Test Cases'!$E$2:$E$165,$B8,'Test Cases'!$M$2:$M$165,"Not Run") | H8: =IFERROR(D8/(D8+E8),0)
B9: P3 | C9: =COUNTIF('Test Cases'!$E$2:$E$165,$B9) | D9: =COUNTIFS('Test Cases'!$E$2:$E$165,$B9,'Test Cases'!$M$2:$M$165,"Pass") | E9: =COUNTIFS('Test Cases'!$E$2:$E$165,$B9,'Test Cases'!$M$2:$M$165,"Fail") | F9: =COUNTIFS('Test Cases'!$E$2:$E$165,$B9,'Test Cases'!$M$2:$M$165,"Blocked") | G9: =COUNTIFS('Test Cases'!$E$2:$E$165,$B9,'Test Cases'!$M$2:$M$165,"Not Run") | H9: =IFERROR(D9/(D9+E9),0)
B10: Total | C10: =SUM(C7:C9) | D10: =SUM(D7:D9) | E10: =SUM(E7:E9) | F10: =SUM(F7:F9) | G10: =SUM(G7:G9) | H10: =IFERROR(D10/(D10+E10),0)
B12: BY TESTING TYPE (one row per testing type; document 07 is charter-based and has no scripted cases)
B13: Type | C13: Planned | D13: Pass | E13: Fail | F13: Blocked | G13: Not Run | H13: Pass rate
B14: Smoke | C14: =COUNTIF('Test Cases'!$D$2:$D$165,$B14) | D14: =COUNTIFS('Test Cases'!$D$2:$D$165,$B14,'Test Cases'!$M$2:$M$165,"Pass") | E14: =COUNTIFS('Test Cases'!$D$2:$D$165,$B14,'Test Cases'!$M$2:$M$165,"Fail") | F14: =COUNTIFS('Test Cases'!$D$2:$D$165,$B14,'Test Cases'!$M$2:$M$165,"Blocked") | G14: =COUNTIFS('Test Cases'!$D$2:$D$165,$B14,'Test Cases'!$M$2:$M$165,"Not Run") | H14: =IFERROR(D14/(D14+E14),0)
B15: Functional | C15: =COUNTIF('Test Cases'!$D$2:$D$165,$B15) | D15: =COUNTIFS('Test Cases'!$D$2:$D$165,$B15,'Test Cases'!$M$2:$M$165,"Pass") | E15: =COUNTIFS('Test Cases'!$D$2:$D$165,$B15,'Test Cases'!$M$2:$M$165,"Fail") | F15: =COUNTIFS('Test Cases'!$D$2:$D$165,$B15,'Test Cases'!$M$2:$M$165,"Blocked") | G15: =COUNTIFS('Test Cases'!$D$2:$D$165,$B15,'Test Cases'!$M$2:$M$165,"Not Run") | H15: =IFERROR(D15/(D15+E15),0)
B16: Negative | C16: =COUNTIF('Test Cases'!$D$2:$D$165,$B16) | D16: =COUNTIFS('Test Cases'!$D$2:$D$165,$B16,'Test Cases'!$M$2:$M$165,"Pass") | E16: =COUNTIFS('Test Cases'!$D$2:$D$165,$B16,'Test Cases'!$M$2:$M$165,"Fail") | F16: =COUNTIFS('Test Cases'!$D$2:$D$165,$B16,'Test Cases'!$M$2:$M$165,"Blocked") | G16: =COUNTIFS('Test Cases'!$D$2:$D$165,$B16,'Test Cases'!$M$2:$M$165,"Not Run") | H16: =IFERROR(D16/(D16+E16),0)
B17: Boundary | C17: =COUNTIF('Test Cases'!$D$2:$D$165,$B17) | D17: =COUNTIFS('Test Cases'!$D$2:$D$165,$B17,'Test Cases'!$M$2:$M$165,"Pass") | E17: =COUNTIFS('Test Cases'!$D$2:$D$165,$B17,'Test Cases'!$M$2:$M$165,"Fail") | F17: =COUNTIFS('Test Cases'!$D$2:$D$165,$B17,'Test Cases'!$M$2:$M$165,"Blocked") | G17: =COUNTIFS('Test Cases'!$D$2:$D$165,$B17,'Test Cases'!$M$2:$M$165,"Not Run") | H17: =IFERROR(D17/(D17+E17),0)
B18: Input Validation | C18: =COUNTIF('Test Cases'!$D$2:$D$165,$B18) | D18: =COUNTIFS('Test Cases'!$D$2:$D$165,$B18,'Test Cases'!$M$2:$M$165,"Pass") | E18: =COUNTIFS('Test Cases'!$D$2:$D$165,$B18,'Test Cases'!$M$2:$M$165,"Fail") | F18: =COUNTIFS('Test Cases'!$D$2:$D$165,$B18,'Test Cases'!$M$2:$M$165,"Blocked") | G18: =COUNTIFS('Test Cases'!$D$2:$D$165,$B18,'Test Cases'!$M$2:$M$165,"Not Run") | H18: =IFERROR(D18/(D18+E18),0)
B19: Destructive | C19: =COUNTIF('Test Cases'!$D$2:$D$165,$B19) | D19: =COUNTIFS('Test Cases'!$D$2:$D$165,$B19,'Test Cases'!$M$2:$M$165,"Pass") | E19: =COUNTIFS('Test Cases'!$D$2:$D$165,$B19,'Test Cases'!$M$2:$M$165,"Fail") | F19: =COUNTIFS('Test Cases'!$D$2:$D$165,$B19,'Test Cases'!$M$2:$M$165,"Blocked") | G19: =COUNTIFS('Test Cases'!$D$2:$D$165,$B19,'Test Cases'!$M$2:$M$165,"Not Run") | H19: =IFERROR(D19/(D19+E19),0)
B20: End-to-End | C20: =COUNTIF('Test Cases'!$D$2:$D$165,$B20) | D20: =COUNTIFS('Test Cases'!$D$2:$D$165,$B20,'Test Cases'!$M$2:$M$165,"Pass") | E20: =COUNTIFS('Test Cases'!$D$2:$D$165,$B20,'Test Cases'!$M$2:$M$165,"Fail") | F20: =COUNTIFS('Test Cases'!$D$2:$D$165,$B20,'Test Cases'!$M$2:$M$165,"Blocked") | G20: =COUNTIFS('Test Cases'!$D$2:$D$165,$B20,'Test Cases'!$M$2:$M$165,"Not Run") | H20: =IFERROR(D20/(D20+E20),0)
B21: Usability | C21: =COUNTIF('Test Cases'!$D$2:$D$165,$B21) | D21: =COUNTIFS('Test Cases'!$D$2:$D$165,$B21,'Test Cases'!$M$2:$M$165,"Pass") | E21: =COUNTIFS('Test Cases'!$D$2:$D$165,$B21,'Test Cases'!$M$2:$M$165,"Fail") | F21: =COUNTIFS('Test Cases'!$D$2:$D$165,$B21,'Test Cases'!$M$2:$M$165,"Blocked") | G21: =COUNTIFS('Test Cases'!$D$2:$D$165,$B21,'Test Cases'!$M$2:$M$165,"Not Run") | H21: =IFERROR(D21/(D21+E21),0)
B22: Accessibility | C22: =COUNTIF('Test Cases'!$D$2:$D$165,$B22) | D22: =COUNTIFS('Test Cases'!$D$2:$D$165,$B22,'Test Cases'!$M$2:$M$165,"Pass") | E22: =COUNTIFS('Test Cases'!$D$2:$D$165,$B22,'Test Cases'!$M$2:$M$165,"Fail") | F22: =COUNTIFS('Test Cases'!$D$2:$D$165,$B22,'Test Cases'!$M$2:$M$165,"Blocked") | G22: =COUNTIFS('Test Cases'!$D$2:$D$165,$B22,'Test Cases'!$M$2:$M$165,"Not Run") | H22: =IFERROR(D22/(D22+E22),0)
B23: Compatibility | C23: =COUNTIF('Test Cases'!$D$2:$D$165,$B23) | D23: =COUNTIFS('Test Cases'!$D$2:$D$165,$B23,'Test Cases'!$M$2:$M$165,"Pass") | E23: =COUNTIFS('Test Cases'!$D$2:$D$165,$B23,'Test Cases'!$M$2:$M$165,"Fail") | F23: =COUNTIFS('Test Cases'!$D$2:$D$165,$B23,'Test Cases'!$M$2:$M$165,"Blocked") | G23: =COUNTIFS('Test Cases'!$D$2:$D$165,$B23,'Test Cases'!$M$2:$M$165,"Not Run") | H23: =IFERROR(D23/(D23+E23),0)
B24: Performance | C24: =COUNTIF('Test Cases'!$D$2:$D$165,$B24) | D24: =COUNTIFS('Test Cases'!$D$2:$D$165,$B24,'Test Cases'!$M$2:$M$165,"Pass") | E24: =COUNTIFS('Test Cases'!$D$2:$D$165,$B24,'Test Cases'!$M$2:$M$165,"Fail") | F24: =COUNTIFS('Test Cases'!$D$2:$D$165,$B24,'Test Cases'!$M$2:$M$165,"Blocked") | G24: =COUNTIFS('Test Cases'!$D$2:$D$165,$B24,'Test Cases'!$M$2:$M$165,"Not Run") | H24: =IFERROR(D24/(D24+E24),0)
B25: Localisation | C25: =COUNTIF('Test Cases'!$D$2:$D$165,$B25) | D25: =COUNTIFS('Test Cases'!$D$2:$D$165,$B25,'Test Cases'!$M$2:$M$165,"Pass") | E25: =COUNTIFS('Test Cases'!$D$2:$D$165,$B25,'Test Cases'!$M$2:$M$165,"Fail") | F25: =COUNTIFS('Test Cases'!$D$2:$D$165,$B25,'Test Cases'!$M$2:$M$165,"Blocked") | G25: =COUNTIFS('Test Cases'!$D$2:$D$165,$B25,'Test Cases'!$M$2:$M$165,"Not Run") | H25: =IFERROR(D25/(D25+E25),0)
B26: Total | C26: =SUM(C14:C25) | D26: =SUM(D14:D25) | E26: =SUM(E14:E25) | F26: =SUM(F14:F25) | G26: =SUM(G14:G25) | H26: =IFERROR(D26/(D26+E26),0)
B28: BY JOURNEY STAGE
B29: Journey Stage | C29: Planned | D29: Pass | E29: Fail | F29: Blocked | G29: Not Run | H29: Pass rate
B30: Discovery | C30: =COUNTIF('Test Cases'!$F$2:$F$165,$B30) | D30: =COUNTIFS('Test Cases'!$F$2:$F$165,$B30,'Test Cases'!$M$2:$M$165,"Pass") | E30: =COUNTIFS('Test Cases'!$F$2:$F$165,$B30,'Test Cases'!$M$2:$M$165,"Fail") | F30: =COUNTIFS('Test Cases'!$F$2:$F$165,$B30,'Test Cases'!$M$2:$M$165,"Blocked") | G30: =COUNTIFS('Test Cases'!$F$2:$F$165,$B30,'Test Cases'!$M$2:$M$165,"Not Run") | H30: =IFERROR(D30/(D30+E30),0)
B31: Consideration | C31: =COUNTIF('Test Cases'!$F$2:$F$165,$B31) | D31: =COUNTIFS('Test Cases'!$F$2:$F$165,$B31,'Test Cases'!$M$2:$M$165,"Pass") | E31: =COUNTIFS('Test Cases'!$F$2:$F$165,$B31,'Test Cases'!$M$2:$M$165,"Fail") | F31: =COUNTIFS('Test Cases'!$F$2:$F$165,$B31,'Test Cases'!$M$2:$M$165,"Blocked") | G31: =COUNTIFS('Test Cases'!$F$2:$F$165,$B31,'Test Cases'!$M$2:$M$165,"Not Run") | H31: =IFERROR(D31/(D31+E31),0)
B32: Conversion | C32: =COUNTIF('Test Cases'!$F$2:$F$165,$B32) | D32: =COUNTIFS('Test Cases'!$F$2:$F$165,$B32,'Test Cases'!$M$2:$M$165,"Pass") | E32: =COUNTIFS('Test Cases'!$F$2:$F$165,$B32,'Test Cases'!$M$2:$M$165,"Fail") | F32: =COUNTIFS('Test Cases'!$F$2:$F$165,$B32,'Test Cases'!$M$2:$M$165,"Blocked") | G32: =COUNTIFS('Test Cases'!$F$2:$F$165,$B32,'Test Cases'!$M$2:$M$165,"Not Run") | H32: =IFERROR(D32/(D32+E32),0)
B33: Account | C33: =COUNTIF('Test Cases'!$F$2:$F$165,$B33) | D33: =COUNTIFS('Test Cases'!$F$2:$F$165,$B33,'Test Cases'!$M$2:$M$165,"Pass") | E33: =COUNTIFS('Test Cases'!$F$2:$F$165,$B33,'Test Cases'!$M$2:$M$165,"Fail") | F33: =COUNTIFS('Test Cases'!$F$2:$F$165,$B33,'Test Cases'!$M$2:$M$165,"Blocked") | G33: =COUNTIFS('Test Cases'!$F$2:$F$165,$B33,'Test Cases'!$M$2:$M$165,"Not Run") | H33: =IFERROR(D33/(D33+E33),0)
B34: Cross-cutting | C34: =COUNTIF('Test Cases'!$F$2:$F$165,$B34) | D34: =COUNTIFS('Test Cases'!$F$2:$F$165,$B34,'Test Cases'!$M$2:$M$165,"Pass") | E34: =COUNTIFS('Test Cases'!$F$2:$F$165,$B34,'Test Cases'!$M$2:$M$165,"Fail") | F34: =COUNTIFS('Test Cases'!$F$2:$F$165,$B34,'Test Cases'!$M$2:$M$165,"Blocked") | G34: =COUNTIFS('Test Cases'!$F$2:$F$165,$B34,'Test Cases'!$M$2:$M$165,"Not Run") | H34: =IFERROR(D34/(D34+E34),0)
B35: Total | C35: =SUM(C30:C34) | D35: =SUM(D30:D34) | E35: =SUM(E30:E34) | F35: =SUM(F30:F34) | G35: =SUM(G30:G34) | H35: =IFERROR(D35/(D35+E35),0)
B37: BY MODULE
B38: Module | C38: Planned | D38: Pass | E38: Fail | F38: Blocked | G38: Not Run | H38: Pass rate
B39: Login & Authentication | C39: =COUNTIF('Test Cases'!$B$2:$B$165,$B39) | D39: =COUNTIFS('Test Cases'!$B$2:$B$165,$B39,'Test Cases'!$M$2:$M$165,"Pass") | E39: =COUNTIFS('Test Cases'!$B$2:$B$165,$B39,'Test Cases'!$M$2:$M$165,"Fail") | F39: =COUNTIFS('Test Cases'!$B$2:$B$165,$B39,'Test Cases'!$M$2:$M$165,"Blocked") | G39: =COUNTIFS('Test Cases'!$B$2:$B$165,$B39,'Test Cases'!$M$2:$M$165,"Not Run") | H39: =IFERROR(D39/(D39+E39),0)
B40: Catalog | C40: =COUNTIF('Test Cases'!$B$2:$B$165,$B40) | D40: =COUNTIFS('Test Cases'!$B$2:$B$165,$B40,'Test Cases'!$M$2:$M$165,"Pass") | E40: =COUNTIFS('Test Cases'!$B$2:$B$165,$B40,'Test Cases'!$M$2:$M$165,"Fail") | F40: =COUNTIFS('Test Cases'!$B$2:$B$165,$B40,'Test Cases'!$M$2:$M$165,"Blocked") | G40: =COUNTIFS('Test Cases'!$B$2:$B$165,$B40,'Test Cases'!$M$2:$M$165,"Not Run") | H40: =IFERROR(D40/(D40+E40),0)
B41: Sorting | C41: =COUNTIF('Test Cases'!$B$2:$B$165,$B41) | D41: =COUNTIFS('Test Cases'!$B$2:$B$165,$B41,'Test Cases'!$M$2:$M$165,"Pass") | E41: =COUNTIFS('Test Cases'!$B$2:$B$165,$B41,'Test Cases'!$M$2:$M$165,"Fail") | F41: =COUNTIFS('Test Cases'!$B$2:$B$165,$B41,'Test Cases'!$M$2:$M$165,"Blocked") | G41: =COUNTIFS('Test Cases'!$B$2:$B$165,$B41,'Test Cases'!$M$2:$M$165,"Not Run") | H41: =IFERROR(D41/(D41+E41),0)
B42: Product Detail | C42: =COUNTIF('Test Cases'!$B$2:$B$165,$B42) | D42: =COUNTIFS('Test Cases'!$B$2:$B$165,$B42,'Test Cases'!$M$2:$M$165,"Pass") | E42: =COUNTIFS('Test Cases'!$B$2:$B$165,$B42,'Test Cases'!$M$2:$M$165,"Fail") | F42: =COUNTIFS('Test Cases'!$B$2:$B$165,$B42,'Test Cases'!$M$2:$M$165,"Blocked") | G42: =COUNTIFS('Test Cases'!$B$2:$B$165,$B42,'Test Cases'!$M$2:$M$165,"Not Run") | H42: =IFERROR(D42/(D42+E42),0)
B43: Cart | C43: =COUNTIF('Test Cases'!$B$2:$B$165,$B43) | D43: =COUNTIFS('Test Cases'!$B$2:$B$165,$B43,'Test Cases'!$M$2:$M$165,"Pass") | E43: =COUNTIFS('Test Cases'!$B$2:$B$165,$B43,'Test Cases'!$M$2:$M$165,"Fail") | F43: =COUNTIFS('Test Cases'!$B$2:$B$165,$B43,'Test Cases'!$M$2:$M$165,"Blocked") | G43: =COUNTIFS('Test Cases'!$B$2:$B$165,$B43,'Test Cases'!$M$2:$M$165,"Not Run") | H43: =IFERROR(D43/(D43+E43),0)
B44: Checkout — Shipping | C44: =COUNTIF('Test Cases'!$B$2:$B$165,$B44) | D44: =COUNTIFS('Test Cases'!$B$2:$B$165,$B44,'Test Cases'!$M$2:$M$165,"Pass") | E44: =COUNTIFS('Test Cases'!$B$2:$B$165,$B44,'Test Cases'!$M$2:$M$165,"Fail") | F44: =COUNTIFS('Test Cases'!$B$2:$B$165,$B44,'Test Cases'!$M$2:$M$165,"Blocked") | G44: =COUNTIFS('Test Cases'!$B$2:$B$165,$B44,'Test Cases'!$M$2:$M$165,"Not Run") | H44: =IFERROR(D44/(D44+E44),0)
B45: Checkout — Payment | C45: =COUNTIF('Test Cases'!$B$2:$B$165,$B45) | D45: =COUNTIFS('Test Cases'!$B$2:$B$165,$B45,'Test Cases'!$M$2:$M$165,"Pass") | E45: =COUNTIFS('Test Cases'!$B$2:$B$165,$B45,'Test Cases'!$M$2:$M$165,"Fail") | F45: =COUNTIFS('Test Cases'!$B$2:$B$165,$B45,'Test Cases'!$M$2:$M$165,"Blocked") | G45: =COUNTIFS('Test Cases'!$B$2:$B$165,$B45,'Test Cases'!$M$2:$M$165,"Not Run") | H45: =IFERROR(D45/(D45+E45),0)
...
